tests/goldens/01302020_first_hour.txt
checkpoint 10000000
554 B 2910300 600 3
554 B 2910200 500 1
554 B 2909900 400 1
554 B 2909500 400 1
554 B 2900100 50 1
554 B 2900000 100 1
554 B 2895300 2000 1
554 B 2852000 1403 1
554 B 2800000 5 1
554 B 2779100 100 1
554 A 2912100 400 1
554 A 2912500 400 1
554 A 2913000 100 1
554 A 2913300 500 1
554 A 2914200 100 1
554 A 2916300 100 1
554 A 2917400 100 1
554 A 2927700 2000 1
554 A 2936000 200 1
554 A 2980000 16 1
682 B 493600 170 1
682 B 493500 2400 8
682 B 493400 2558 7
682 B 493300 2350 2
682 B 493200 2400 2
682 B 493100 2000 1
682 B 492500 1000 2
682 B 491500 100 1
682 B 491000 100 1
682 B 471100 100 1
682 A 493800 300 1
682 A 493900 794 2
682 A 494000 1794 7
682 A 494100 1380 5
682 A 494200 900 1
682 A 494500 100 1
682 A 495000 100 1
682 A 510000 10 1
682 A 516100 100 1
682 A 550000 100 1
743 B 445400 800 2
743 B 445300 1600 4
743 B 445200 1700 6
743 B 445100 1800 6
743 B 445000 1100 4
743 B 444900 1200 5
743 B 444800 700 2
743 B 444700 700 2
743 B 444600 2100 4
743 B 444500 600 1
743 A 445800 1200 5
743 A 445900 1800 7
743 A 446000 1700 3
743 A 446100 1000 2
743 A 446200 600 1
743 A 446300 2100 2
743 A 446400 600 1
743 A 446500 600 1
743 A 446600 600 1
743 A 451800 112 1
1106 B 438800 100 1
1106 B 438700 2100 9
1106 B 438600 1700 7
1106 B 438500 1200 3
1106 B 438400 1200 1
1106 B 438300 1500 2
1106 B 438000 1500 1
1106 B 427500 46 1
1106 B 424000 10 1
1106 B 418900 100 1
1106 A 439200 900 4
1106 A 439300 1400 6
1106 A 439400 1300 4
1106 A 439500 500 1
1106 A 439600 100 1
1106 A 439900 1500 1
1106 A 458900 100 1
1106 A 470000 30 1
1106 A 490000 100 1
1106 A 493700 49 1
1969 B 1585400 400 1
1969 B 1585300 100 1
1969 B 1585100 100 1
1969 B 1585000 400 1
1969 B 1584800 200 1
1969 B 1584600 400 1
1969 B 1581700 1500 1
1969 B 1573500 30 1
1969 B 1553500 30 1
1969 B 1530000 200 1
1969 A 1586400 400 1
1969 A 1586700 600 2
1969 A 1586800 400 1
1969 A 1586900 200 1
1969 A 1588700 1500 1
1969 A 1591600 100 1
1969 A 1657800 100 1
1969 A 1880000 1 1
1969 A 3216600 7 1
3545 B 469300 600 2
3545 B 469200 2100 4
3545 B 469100 1500 3
3545 B 469000 1600 3
3545 B 468900 800 1
3545 B 468800 900 1
3545 B 468200 3000 1
3545 B 460000 1 1
3545 B 450000 3 1
3545 B 448000 100 1
3545 A 469600 1400 2
3545 A 469700 1400 4
3545 A 469800 2000 7
3545 A 469900 900 2
3545 A 470000 100 1
3545 A 470300 3000 1
3545 A 485500 100 1
3545 A 490700 100 1
3545 A 495000 40 1
3545 A 517000 10 1
3819 B 367100 600 5
3819 B 367000 3700 9
3819 B 366900 3900 5
3819 B 366800 3200 9
3819 B 366700 2700 8
3819 B 366600 2500 1
3819 B 366500 1400 1
3819 B 366400 1500 1
3819 B 360000 40 5
3819 B 354000 150 1
3819 A 367400 1500 7
3819 A 367500 4100 8
3819 A 367600 1200 4
3819 A 367700 100 1
3819 A 367800 200 1
3819 A 367900 1500 1
3819 A 368100 200 1
3819 A 383800 100 1
5304 B 150600 6600 7
5304 B 150500 4300 5
5304 B 150400 4400 6
5304 B 150300 4500 7
5304 B 150200 4100 11
5304 B 150100 7000 2
5304 B 150000 2700 1
5304 B 143600 100 1
5304 B 130000 1000 1
5304 A 150900 3300 8
5304 A 151000 1700 3
5304 A 151100 1800 2
5304 A 151200 4000 2
5304 A 151300 1000 1
5304 A 151400 1000 1
5304 A 157400 100 1
5304 A 180000 200 1
5304 A 274800 105 1
5304 A 400000 18 1
5508 B 665300 700 2
5508 B 665200 1296 3
5508 B 665100 600 2
5508 B 665000 530 2
5508 B 664900 100 1
5508 B 664400 1500 1
5508 B 663900 450 4
5508 B 655600 20 1
5508 B 635300 100 1
5508 B 623000 30 1
5508 A 665800 672 2
5508 A 665900 500 2
5508 A 666000 989 6
5508 A 666100 824 4
5508 A 666200 594 2
5508 A 666300 500 2
5508 A 666400 101 1
5508 A 666800 1793 2
5508 A 675400 10 1
5508 A 696000 100 1
6470 B 356800 130 2
6470 B 356700 1400 5
6470 B 356600 600 5
6470 B 356500 300 3
6470 B 356200 400 1
6470 B 355800 3000 1
6470 B 340700 100 1
6470 A 357200 100 1
6470 A 357300 1500 7
6470 A 357400 1600 7
6470 A 357500 200 2
6470 A 357900 3000 1
6470 A 373200 100 1
6470 A 725200 30 1
6550 B 1304900 200 1
6550 B 1304800 200 1
6550 B 1304700 200 1
6550 B 1303800 1000 1
6550 B 1303500 1000 1
6550 B 1303200 1000 1
6550 B 1302900 1000 1
6550 B 1302600 1000 1
6550 B 1302300 1000 1
6550 B 1301200 100 1
6550 A 1305900 200 1
6550 A 1306800 1000 1
6550 A 1307100 1000 1
6550 A 1307400 1000 1
6550 A 1307700 1000 1
6550 A 1308000 1000 1
6550 A 1308300 1000 1
6550 A 1309400 100 1
6550 A 1312400 100 1
6550 A 1312700 100 1
6562 B 2204500 1900 3
6562 B 2204400 1800 3
6562 B 2204300 2723 5
6562 B 2204200 1800 3
6562 B 2204100 2723 5
6562 B 2204000 1700 3
6562 B 2203900 1500 2
6562 B 2203800 900 2
6562 B 2203700 200 1
6562 B 2203600 200 1
6562 A 2204800 200 1
6562 A 2204900 1123 3
6562 A 2205000 1900 4
6562 A 2205100 1800 3
6562 A 2205200 900 2
6562 A 2205300 800 1
6562 A 2205400 200 1
6562 A 2206000 1000 1
6562 A 2206500 1000 1
6562 A 2206800 100 1
6650 B 539100 1899 8
6650 B 539000 3453 6
6650 B 538900 1974 2
6650 B 538800 400 1
6650 B 538700 600 2
6650 B 538600 400 1
6650 B 537500 16 1
6650 B 536400 1500 1
6650 B 535200 50 1
6650 B 535000 190 2
6650 A 539600 400 1
6650 A 539700 512 2
6650 A 539800 927 3
6650 A 539900 1245 6
6650 A 540000 400 1
6650 A 540100 400 1
6650 A 540200 400 1
6650 A 540300 191 1
6650 A 540600 259 1
6650 A 541200 50 1
6651 B 548900 100 1
6651 B 548800 215 2
6651 B 548700 615 2
6651 B 548600 600 2
6651 B 548500 200 1
6651 B 548400 200 1
6651 B 548300 330 3
6651 B 548200 200 1
6651 B 548100 200 1
6651 B 548000 200 1
6651 A 549200 200 1
6651 A 549300 200 1
6651 A 549400 200 2
6651 A 549500 1024 4
6651 A 549600 200 1
6651 A 549700 582 3
6651 A 549800 200 1
6651 A 550200 100 1
6651 A 550300 3100 1
6651 A 550600 216 1
6754 B 548000 600 2
6754 B 547900 1400 6
6754 B 547800 1449 7
6754 B 547700 734 3
6754 B 547600 652 3
6754 B 547500 873 3
6754 B 546800 1500 1
6754 B 540000 100 1
6754 B 522300 100 1
6754 B 200000 160 1
6754 A 548500 700 3
6754 A 548600 1300 4
6754 A 548700 400 1
6754 A 548800 1610 2
6754 A 572300 100 1
6754 A 599300 10 1
6754 A 1105000 20 1
6966 B 1301600 203 2
6966 B 1301500 300 1
6966 B 1301400 1500 1
6966 B 1301300 1234 4
6966 B 1301100 1800 6
6966 B 1301000 1010 4
6966 B 1300600 300 1
6966 B 1299200 2000 1
6966 B 1290100 100 1
6966 B 1288800 10 1
6966 A 1302300 300 1
6966 A 1302400 618 1
6966 A 1302700 300 1
6966 A 1303000 264 2
6966 A 1303100 300 1
6966 A 1303200 110 1
6966 A 1304900 2000 1
6966 A 1360700 100 1
6966 A 1510000 1 1
6966 A 2633000 7 1
7457 B 3245400 3200 3
7457 B 3245300 200 1
7457 B 3245200 1300 2
7457 B 3245100 301 3
7457 B 3245000 501 3
7457 B 3244900 201 2
7457 B 3244800 330 2
7457 B 3244700 1 1
7457 B 3244600 300 1
7457 B 3244500 2 2
7457 A 3245800 2000 2
7457 A 3245900 700 2
7457 A 3246000 202 3
7457 A 3246100 200 1
7457 A 3246200 300 2
7457 A 3246300 200 1
7457 A 3246500 1 1
7457 A 3246600 300 1
7457 A 3246800 300 1
7457 A 3247000 2 2
7939 B 956600 620 2
7939 B 956500 825 2
7939 B 956400 825 2
7939 B 956300 825 2
7939 B 956200 214 2
7939 B 956100 625 1
7939 B 956000 625 1
7939 B 955600 625 1
7939 B 955500 450 3
7939 B 955300 2000 2
7939 A 957000 625 1
7939 A 957100 825 2
7939 A 957200 825 2
7939 A 957300 825 2
7939 A 957400 625 1
7939 A 957700 625 1
7939 A 957800 15 1
7939 A 958000 1000 1
7939 A 958200 1036 2
7939 A 958400 1000 1
8170 B 576900 400 1
8170 B 576800 1049 3
8170 B 576700 2748 9
8170 B 576600 1489 6
8170 B 576500 2719 2
8170 B 576400 400 1
8170 B 576300 1273 3
8170 B 576200 543 2
8170 B 576100 700 5
8170 B 575600 3000 1
8170 A 577300 1345 6
8170 A 577400 1587 6
8170 A 577500 4604 9
8170 A 577600 400 1
8170 A 577700 400 1
8170 A 577800 400 1
8170 A 577900 400 1
8170 A 578800 3000 1
8170 A 590000 15 1
8170 A 593700 88 1
8655 B 627500 1470 5
8655 B 627400 784 3
8655 B 627300 626 2
8655 B 627200 200 1
8655 B 627100 530 2
8655 B 626900 291 2
8655 B 625900 3000 1
8655 B 598700 100 1
8655 B 360300 100 1
8655 B 346100 100 1
8655 A 628200 940 2
8655 A 628300 700 2
8655 A 628400 455 2
8655 A 628500 810 3
8655 A 629700 3000 1
8655 A 656000 100 1
8655 A 899100 100 1
8655 A 913300 100 1
8655 A 1281600 20 1
8655 A 1999999900 100 1
checkpoint 20000000
554 B 2915100 1 1
554 B 2914800 58 2
554 B 2913900 300 1
554 B 2913500 300 1
